Workbook
Name average: '[1]Sub Contact'!#REF!
Name IP_PBX: #REF!
Name OLE_LINK1: #REF!
Name Type: #REF!
Name ตารางวางบิล2: #REF!

Sheet ภาพรวม
A1: โครงการเพิ่มประสิทธิภาพระบบโครงข่ายสื่อสารด้วยอุปกรณ์ทวนสัญญาณผ่านคลื่นความถี่สูง (SHF)
A2: เพื่อสนับสนุนการปฏิบัติราชการและแก้ไขปัญหาให้กับประชาชนพื้นที่ห่างไกล สัญญาเลขที่ 8680228 ลงวันที่ 23 กรกฎาคม 2568
A4: สรุปภาพรวมแผนงานการติดตั้งเสาสัญญาณระบบวิทยุสื่อสาร ในพื้นที่ 10 จังหวัด | S4: 31 มี.ค. 69
A5: ลำดับ | B5: พื้นที่ภาค | C5: เสาสัญญาณระบบวิทยุสื่อสาร | H5: การดำเนินงานติดตั้งเสาสัญญาณระบบวิทยุสื่อสาร
C6: 60 เมตร | D6: เสารับ-ส่งสัญญาณ | G6: จำนวนทั้งสิ้น | H6: 60 เมตร | K6: เสารับ-ส่งสัญญาณ
K7: 9 เมตร | N7: 18 เมตร | Q7: 30 เมตร
D8: 9 เมตร | E8: 18 เมตร | F8: 30 เมตร | H8: อยู่ระหว่างการติดตั้ง | I8: เสร็จแล้ว | J8: คงเหลือ | K8: อยู่ระหว่างการติดตั้ง | L8: เสร็จแล้ว | M8: คงเหลือ | N8: อยู่ระหว่างการติดตั้ง | O8: เสร็จแล้ว | P8: คงเหลือ | Q8: อยู่ระหว่างการติดตั้ง | R8: เสร็จแล้ว | S8: คงเหลือ
A9: 1 | B9: กำแพงเพชร | C9: 2 | D9: 15 | E9: 1 | F9: 0 | G9: =C9+D9+E9+F9 -> 18 | H9: 0 | I9: 2 | J9: =C9-H9-I9 -> 0 | K9: 0 | L9: 15 | M9: =D9-K9-L9 -> 0 | N9: 0 | O9: 1 | P9: =E9-N9-O9 -> 0 | Q9: 0 | R9: 0 | S9: =F9-Q9-R9 -> 0
A10: 2 | B10: นครสวรรค์ | C10: 0 | D10: 5 | E10: 0 | F10: 0 | G10: =C10+D10+E10+F10 -> 5 | H10: 0 | I10: 0 | J10: =C10-H10-I10 -> 0 | K10: 5 | L10: 0 | M10: =D10-K10-L10 -> 0 | N10: 0 | O10: 0 | P10: =E10-N10-O10 -> 0 | Q10: 0 | R10: 0 | S10: =F10-Q10-R10 -> 0
A11: 3 | B11: พิจิตร | C11: 2 | D11: 4 | E11: 0 | F11: 0 | G11: =C11+D11+E11+F11 -> 6 | H11: 0 | I11: 2 | J11: =C11-H11-I11 -> 0 | K11: 0 | L11: 4 | M11: =D11-K11-L11 -> 0 | N11: 0 | O11: 0 | P11: =E11-N11-O11 -> 0 | Q11: 0 | R11: 0 | S11: =F11-Q11-R11 -> 0
A12: 4 | B12: เพชรบูรณ์ | C12: 0 | D12: 20 | E12: 1 | F12: 1 | G12: =C12+D12+E12+F12 -> 22 | H12: 0 | I12: 0 | J12: =C12-H12-I12 -> 0 | K12: 0 | L12: 20 | M12: =D12-K12-L12 -> 0 | N12: 0 | O12: 1 | P12: =E12-N12-O12 -> 0 | Q12: 0 | R12: 1 | S12: =F12-Q12-R12 -> 0
A13: 5 | B13: ขอนแก่น | C13: 2 | D13: 26 | E13: 1 | F13: 0 | G13: =C13+D13+E13+F13 -> 29 | H13: 0 | I13: 2 | J13: =C13-H13-I13 -> 0 | K13: 0 | L13: 26 | M13: =D13-K13-L13 -> 0 | N13: 0 | O13: 1 | P13: =E13-N13-O13 -> 0 | Q13: 0 | R13: 0 | S13: =F13-Q13-R13 -> 0
A14: 6 | B14: นครราชสีมา | C14: 2 | D14: 22 | E14: 2 | F14: 0 | G14: =C14+D14+E14+F14 -> 26 | H14: 0 | I14: 2 | J14: =C14-H14-I14 -> 0 | K14: 0 | L14: 22 | M14: =D14-K14-L14 -> 0 | N14: 0 | O14: 2 | P14: =E14-N14-O14 -> 0 | Q14: 0 | R14: 0 | S14: =F14-Q14-R14 -> 0
A15: 7 | B15: จันทบุรี | C15: 2 | D15: 14 | E15: 2 | F15: 0 | G15: =C15+D15+E15+F15 -> 18 | H15: 0 | I15: 2 | J15: =C15-H15-I15 -> 0 | K15: 0 | L15: 14 | M15: =D15-K15-L15 -> 0 | N15: 0 | O15: 2 | P15: =E15-N15-O15 -> 0 | Q15: 0 | R15: 0 | S15: =F15-Q15-R15 -> 0
A16: 8 | B16: กาญจนบุรี | C16: 2 | D16: 29 | E16: 1 | F16: 0 | G16: =C16+D16+E16+F16 -> 32 | H16: 0 | I16: 2 | J16: =C16-H16-I16 -> 0 | K16: 0 | L16: 29 | M16: =D16-K16-L16 -> 0 | N16: 0 | O16: 1 | P16: =E16-N16-O16 -> 0 | Q16: 0 | R16: 0 | S16: =F16-Q16-R16 -> 0
A17: 9 | B17: ตรัง | C17: 2 | D17: 14 | E17: 1 | F17: 2 | G17: =C17+D17+E17+F17 -> 19 | H17: 1 | I17: 1 | J17: =C17-H17-I17 -> 0 | K17: 0 | L17: 13 | M17: =D17-K17-L17 -> 1 | N17: 0 | O17: 1 | P17: =E17-N17-O17 -> 0 | Q17: 0 | R17: 2 | S17: =F17-Q17-R17 -> 0
A18: 10 | B18: นครศรีธรรมราช | C18: 2 | D18: 20 | E18: 0 | F18: 0 | G18: =C18+D18+E18+F18 -> 22 | H18: 0 | I18: 1 | J18: =C18-H18-I18 -> 1 | K18: 16 | L18: 4 | M18: =D18-K18-L18 -> 0 | N18: 0 | O18: 0 | P18: =E18-N18-O18 -> 0 | Q18: 0 | R18: 0 | S18: =F18-Q18-R18 -> 0
A19: รวม | C19: =SUM(C9:C18) -> 16 | D19: =SUM(D9:D18) -> 169 | E19: =SUM(E9:E18) -> 9 | F19: =SUM(F9:F18) -> 3 | G19: =SUM(G9:G18) -> 197 | H19: =SUM(H9:H18) -> 1 | I19: =SUM(I9:I18) -> 14 | J19: =SUM(J9:J18) -> 1 | ... S19: =SUM(S9:S18) -> 0
B21: สรุป | C21: ความสูงเสาสัญญาณระบบวิทยุสื่อสาร | N21: เสาสูง 60 ม | O21: 16 | P21: 14 | Q21: =P21/O21 -> 0.875 | R21: เสร็จ
B22: สถานที่ติดตั้ง | C22: 60 เมตร | D22: 9 เมตร | E22: 18 เมตร | F22: 30 เมตร | P22: =J19 -> 1 | Q22: =P22/O21 -> 0.0625 | R22: ยังไม่ได้ติดตั้ง
B23: ที่ว่าการอำเภอ | C23: 8 | D23: =IF( COUNTIFS('เสา 9,18,30'!$H$10:$H$189, B23, 'เสา 9,18,30'!$M$10:$M$189, "9")=0, "", COUNTIFS('เสา 9,18,30'!$H$10:$H$189, B23, 'เสา 9,18,30'!$M$10:$M$189, "9") ) | E23: =IF( COUNTIFS('เสา 9,18,30'!$H$10:$H$189, B23, 'เสา 9,18,30'!$M$10:$M$189, "18")=0, "", COUNTIFS('เสา 9,18,30'!$H$10:$H$189, B23, 'เสา 9,18,30'!$M$10:$M$189, "18") ) | F23: =IF( COUNTIFS('เสา 9,18,30'!$H$10:$H$189,B23, 'เสา 9,18,30'!$M$10:$M$189,"30")=0, "", COUNTIFS('เสา 9,18,30'!$H$10:$H$189,B23, 'เสา 9,18,30'!$M$10:$M$189,"30") ) | N23: เสาสูง 9, 18, 30 ม | O23: 181 | P23: =L19+O19+R19 -> 159 | Q23: =P23/O23 -> 0.87845304 | R23: เสร็จ
B24: อบต. | C24: =IF( SUM(COUNTIFS('เสา 60'!$H$10:$H$23,B24))=0, "", SUM(COUNTIFS('เสา 60'!$H$10:$H$23,B24)) ) -> 4 | D24: =IF( COUNTIFS('เสา 9,18,30'!$H$10:$H$189, B24, 'เสา 9,18,30'!$M$10:$M$189, "9")=0, "", COUNTIFS('เสา 9,18,30'!$H$10:$H$189, B24, 'เสา 9,18,30'!$M$10:$M$189, "9") ) | E24: =IF( COUNTIFS('เสา 9,18,30'!$H$10:$H$189, B24, 'เสา 9,18,30'!$M$10:$M$189, "18")=0, "", COUNTIFS('เสา 9,18,30'!$H$10:$H$189, B24, 'เสา 9,18,30'!$M$10:$M$189, "18") ) | F24: =IF( COUNTIFS('เสา 9,18,30'!$H$10:$H$189,B24, 'เสา 9,18,30'!$M$10:$M$189,"30")=0, "", COUNTIFS('เสา 9,18,30'!$H$10:$H$189,B24, 'เสา 9,18,30'!$M$10:$M$189,"30") ) | P24: =K19 -> 21 | Q24: =P24/O23 -> 0.1160221 | R24: กำลังติดตั้ง
B25: ทต. | C25: =IF( SUM(COUNTIFS('เสา 60'!$H$10:$H$23,B25))=0, "", SUM(COUNTIFS('เสา 60'!$H$10:$H$23,B25)) ) -> 1 | D25: =IF( COUNTIFS('เสา 9,18,30'!$H$10:$H$189, B25, 'เสา 9,18,30'!$M$10:$M$189, "9")=0, "", COUNTIFS('เสา 9,18,30'!$H$10:$H$189, B25, 'เสา 9,18,30'!$M$10:$M$189, "9") ) | F25: =IF( COUNTIFS('เสา 9,18,30'!$H$10:$H$189,B25, 'เสา 9,18,30'!$M$10:$M$189,"30")=0, "", COUNTIFS('เสา 9,18,30'!$H$10:$H$189,B25, 'เสา 9,18,30'!$M$10:$M$189,"30") ) | P25: =M19 -> 1 | Q25: =P25/O23 -> 0.0055248619 | R25: ยังไม่ได้ติดตั้ง
B26: ศาลาประชาคม | C26: =IF( SUM(COUNTIFS('เสา 60'!$H$10:$H$23,B26))=0, "", SUM(COUNTIFS('เสา 60'!$H$10:$H$23,B26)) ) -> 1 | D26: 8 | E26: =IF( COUNTIFS('เสา 9,18,30'!$H$10:$H$189, B26, 'เสา 9,18,30'!$M$10:$M$189, "18")=0, "", COUNTIFS('เสา 9,18,30'!$H$10:$H$189, B26, 'เสา 9,18,30'!$M$10:$M$189, "18") ) -> 3 | F26: =IF( COUNTIFS('เสา 9,18,30'!$H$10:$H$189,B26, 'เสา 9,18,30'!$M$10:$M$189,"30")=0, "", COUNTIFS('เสา 9,18,30'!$H$10:$H$189,B26, 'เสา 9,18,30'!$M$10:$M$189,"30") )
B27: ที่ทำการกองทุนหมู่บ้าน (กทบ.) | C27: =IF( SUM(COUNTIFS('เสา 60'!$H$10:$H$23,B27))=0, "", SUM(COUNTIFS('เสา 60'!$H$10:$H$23,B27)) ) -> 1 | D27: =IF( COUNTIFS('เสา 9,18,30'!$H$10:$H$189, B27, 'เสา 9,18,30'!$M$10:$M$189, "9")=0, "", COUNTIFS('เสา 9,18,30'!$H$10:$H$189, B27, 'เสา 9,18,30'!$M$10:$M$189, "9") ) | E27: =IF( COUNTIFS('เสา 9,18,30'!$H$10:$H$189, B27, 'เสา 9,18,30'!$M$10:$M$189, "18")=0, "", COUNTIFS('เสา 9,18,30'!$H$10:$H$189, B27, 'เสา 9,18,30'!$M$10:$M$189, "18") ) | F27: =IF( COUNTIFS('เสา 9,18,30'!$H$10:$H$189,B27, 'เสา 9,18,30'!$M$10:$M$189,"30")=0, "", COUNTIFS('เสา 9,18,30'!$H$10:$H$189,B27, 'เสา 9,18,30'!$M$10:$M$189,"30") ) | N27: เสาสูง 9, 18, 30, 60 ม | O27: =O21+O23 -> 197 | P27: =P21+P23 -> 173 | Q27: =P27/O27 -> 0.87817259 | R27: เสร็จ
B28: วัด | C28: 1 | P28: =P24 -> 21 | Q28: =P28/O27 -> 0.10659898 | R28: กำลังติดตั้ง
B29: ที่ทำการบ้าน กำนัน | C29: =IF( SUM(COUNTIFS('เสา 60'!$H$10:$H$23,B29))=0, "", SUM(COUNTIFS('เสา 60'!$H$10:$H$23,B29)) ) | D29: 9 | E29: =IF( COUNTIFS('เสา 9,18,30'!$H$10:$H$189, B29, 'เสา 9,18,30'!$M$10:$M$189, "18")=0, "", COUNTIFS('เสา 9,18,30'!$H$10:$H$189, B29, 'เสา 9,18,30'!$M$10:$M$189, "18") ) | F29: =IF( COUNTIFS('เสา 9,18,30'!$H$10:$H$189,B29, 'เสา 9,18,30'!$M$10:$M$189,"30")=0, "", COUNTIFS('เสา 9,18,30'!$H$10:$H$189,B29, 'เสา 9,18,30'!$M$10:$M$189,"30") ) | P29: =P22+P25 -> 2 | Q29: =P29/O27 -> 0.010152284 | R29: ยังไม่ได้ติดตั้ง
B30: ที่ทำการบ้านผู้ช่วย กำนัน | C30: =IF( SUM(COUNTIFS('เสา 60'!$H$10:$H$23,B30))=0, "", SUM(COUNTIFS('เสา 60'!$H$10:$H$23,B30)) ) | D30: =IF( COUNTIFS('เสา 9,18,30'!$H$10:$H$189, B30, 'เสา 9,18,30'!$M$10:$M$189, "9")=0, "", COUNTIFS('เสา 9,18,30'!$H$10:$H$189, B30, 'เสา 9,18,30'!$M$10:$M$189, "9") ) -> 1 | E30: =IF( COUNTIFS('เสา 9,18,30'!$H$10:$H$189, B30, 'เสา 9,18,30'!$M$10:$M$189, "18")=0, "", COUNTIFS('เสา 9,18,30'!$H$10:$H$189, B30, 'เสา 9,18,30'!$M$10:$M$189, "18") ) | F30: =IF( COUNTIFS('เสา 9,18,30'!$H$10:$H$189,B30, 'เสา 9,18,30'!$M$10:$M$189,"30")=0, "", COUNTIFS('เสา 9,18,30'!$H$10:$H$189,B30, 'เสา 9,18,30'!$M$10:$M$189,"30") )
B31: ที่ทำการสารวัตรกำนัน | C31: =IF( SUM(COUNTIFS('เสา 60'!$H$10:$H$23,B31))=0, "", SUM(COUNTIFS('เสา 60'!$H$10:$H$23,B31)) ) | D31: =IF( COUNTIFS('เสา 9,18,30'!$H$10:$H$189, B31, 'เสา 9,18,30'!$M$10:$M$189, "9")=0, "", COUNTIFS('เสา 9,18,30'!$H$10:$H$189, B31, 'เสา 9,18,30'!$M$10:$M$189, "9") ) -> 1 | E31: =IF( COUNTIFS('เสา 9,18,30'!$H$10:$H$189, B31, 'เสา 9,18,30'!$M$10:$M$189, "18")=0, "", COUNTIFS('เสา 9,18,30'!$H$10:$H$189, B31, 'เสา 9,18,30'!$M$10:$M$189, "18") ) | F31: =IF( COUNTIFS('เสา 9,18,30'!$H$10:$H$189,B31, 'เสา 9,18,30'!$M$10:$M$189,"30")=0, "", COUNTIFS('เสา 9,18,30'!$H$10:$H$189,B31, 'เสา 9,18,30'!$M$10:$M$189,"30") )
B32: ที่ทำการบ้าน ผญบ. | C32: =IF( SUM(COUNTIFS('เสา 60'!$H$10:$H$23,B32))=0, "", SUM(COUNTIFS('เสา 60'!$H$10:$H$23,B32)) ) | D32: 135 | E32: =IF( COUNTIFS('เสา 9,18,30'!$H$10:$H$189, B32, 'เสา 9,18,30'!$M$10:$M$189, "18")=0, "", COUNTIFS('เสา 9,18,30'!$H$10:$H$189, B32, 'เสา 9,18,30'!$M$10:$M$189, "18") ) -> 5 | F32: 3
B33: ที่ทำการบ้านผู้ช่วย ผญบ. | C33: =IF( SUM(COUNTIFS('เสา 60'!$H$10:$H$23,B33))=0, "", SUM(COUNTIFS('เสา 60'!$H$10:$H$23,B33)) ) | D33: 12 | E33: =IF( COUNTIFS('เสา 9,18,30'!$H$10:$H$189, B33, 'เสา 9,18,30'!$M$10:$M$189, "18")=0, "", COUNTIFS('เสา 9,18,30'!$H$10:$H$189, B33, 'เสา 9,18,30'!$M$10:$M$189, "18") ) -> 1 | F33: =IF( COUNTIFS('เสา 9,18,30'!$H$10:$H$189,B33, 'เสา 9,18,30'!$M$10:$M$189,"30")=0, "", COUNTIFS('เสา 9,18,30'!$H$10:$H$189,B33, 'เสา 9,18,30'!$M$10:$M$189,"30") )
B34: ศูนย์เรียนรู้ฯ | C34: =IF( SUM(COUNTIFS('เสา 60'!$H$10:$H$23,B34))=0, "", SUM(COUNTIFS('เสา 60'!$H$10:$H$23,B34)) ) | D34: =IF( COUNTIFS('เสา 9,18,30'!$H$10:$H$189, B34, 'เสา 9,18,30'!$M$10:$M$189, "9")=0, "", COUNTIFS('เสา 9,18,30'!$H$10:$H$189, B34, 'เสา 9,18,30'!$M$10:$M$189, "9") ) -> 1 | E34: =IF( COUNTIFS('เสา 9,18,30'!$H$10:$H$189, B34, 'เสา 9,18,30'!$M$10:$M$189, "18")=0, "", COUNTIFS('เสา 9,18,30'!$H$10:$H$189, B34, 'เสา 9,18,30'!$M$10:$M$189, "18") ) | F34: =IF( COUNTIFS('เสา 9,18,30'!$H$10:$H$189,B34, 'เสา 9,18,30'!$M$10:$M$189,"30")=0, "", COUNTIFS('เสา 9,18,30'!$H$10:$H$189,B34, 'เสา 9,18,30'!$M$10:$M$189,"30") )
B35: อบต. | D35: 1 | E35: =IF( COUNTIFS('เสา 9,18,30'!$H$10:$H$189, B35, 'เสา 9,18,30'!$M$10:$M$189, "18")=0, "", COUNTIFS('เสา 9,18,30'!$H$10:$H$189, B35, 'เสา 9,18,30'!$M$10:$M$189, "18") ) | F35: =IF( COUNTIFS('เสา 9,18,30'!$H$10:$H$189,B35, 'เสา 9,18,30'!$M$10:$M$189,"30")=0, "", COUNTIFS('เสา 9,18,30'!$H$10:$H$189,B35, 'เสา 9,18,30'!$M$10:$M$189,"30") )
B36: ยังไม่สามารถระบุสถานีที่ได้ | D36: 1 | E36: =IF( COUNTIFS('เสา 9,18,30'!$H$10:$H$189, B36, 'เสา 9,18,30'!$M$10:$M$189, "18")=0, "", COUNTIFS('เสา 9,18,30'!$H$10:$H$189, B36, 'เสา 9,18,30'!$M$10:$M$189, "18") ) | F36: =IF( COUNTIFS('เสา 9,18,30'!$H$10:$H$189,B36, 'เสา 9,18,30'!$M$10:$M$189,"30")=0, "", COUNTIFS('เสา 9,18,30'!$H$10:$H$189,B36, 'เสา 9,18,30'!$M$10:$M$189,"30") )
B37: รวม | C37: =SUM(C23:C34) -> 16 | D37: =SUM(D23:D36) -> 169 | E37: =SUM(E23:E34) -> 9 | F37: =SUM(F23:F34) -> 3 | G37: =SUM(C37:F37) -> 197

Sheet เสา 60
A1: โครงการเพิ่มประสิทธิภาพระบบโครงข่ายสื่อสารด้วยอุปกรณ์ทวนสัญญาณผ่านคลื่นความถี่สูง (SHF) เพื่อสนับสนุนการปฏิบัติราชการและแก้ไขปัญหาให้กับประชาชนในพื้นที่ห่างไกล สัญญาเลขที่ ๘๖๘๐๒๒๘
A2: ลงวันที่ ๒๓ กรกฎาคม ๒๕๖๘ | S2: 17 มี.ค. 69
A4: บัญชีรายชื่อสถานที่ติดตั้งเสาสัญญาณระบบวิทยุสื่อสาร
A5: ลำดับ | B5: สถานที่ติดตั้ง | C5: ตำบล | D5: อำเภอ | E5: จังหวัด | F5: เขตพื้นที่รับผิดชอบศูนย์สื่อสารกรมการปกครองเขต | G5: ภาค | H5: พื้นที่ | I5: ผู้รับเหมาเสา | J5: ชนิดของเสา | K5: ความสูงเสา (เมตร) | L5: Sea level (เมตร) | M5: Latitude | N5: Longitude | O5: ติดตั้งฐานรากและโครงสร้างเสาระบบวิทยุสื่อสาร
O6: ปฏิบัติ (เริ่ม) | P6: ปฏิบัติ (เสร็จ) | Q6: จำนวนแท่งกราวด์ | R6: ค่ากราวด์ <= 5 Ohm | S6: สถานะ
B7: =SUBTOTAL(3,B10:B23) -> 14 | C7: =SUBTOTAL(3,C10:C23) -> 14 | D7: =SUBTOTAL(3,D10:D23) -> 14 | E7: =SUBTOTAL(3,E10:E23) -> 14 | F7: =SUBTOTAL(3,F10:F23) -> 14 | G7: =SUBTOTAL(3,G10:G23) -> 14 | H7: =SUBTOTAL(3,H10:H23) -> 14 | I7: =SUBTOTAL(3,I10:I23) -> 14 | ... S7: =SUBTOTAL(3,S10:S23) -> 14
A8: 1 | B8: ที่ว่าการอำเภอคลองลาน | C8: คลองน้ำไหล | D8: คลองลาน | E8: กำแพงเพชร | F8: เขต 3 (ส่วนแยกตาก) | G8: ภาคเหนือ | H8: ที่ว่าการอำเภอ | I8: P&S | J8: Self-Support | K8: 60 | L8: 158 | M8: 16.204197 | N8: 99.321011 | O8: 244359 | P8: 244373 | Q8: 4 | S8: =IF(P8<>"", "Complete", IF(O8<>"", "In progress", "")) -> Complete
A9: 2 | B9: ที่ว่าการอำเภอดงเจริญ | C9: วังงิ้วภาคใต้ | D9: ดงเจริญ | E9: พิจิตร | F9: เขต 3 (พิษณุโลก) | G9: ภาคเหนือ | H9: ที่ว่าการอำเภอ | I9: P&S | J9: Self-Support | K9: 60 | L9: 55 | M9: 16.029156 | N9: 100.62781 | O9: 244359 | P9: 244374 | Q9: 4 | S9: =IF(P9<>"", "Complete", IF(O9<>"", "In progress", "")) -> Complete
A10: 3 | B10: ที่ว่าการอำเภอห้วยกระเจา | C10: ห้วยกระเจา | D10: ห้วยกระเจา | E10: กาญจนบุรี | F10: เขต 11 (เพชรบุรี) | G10: ภาคตะวันตก | H10: ที่ว่าการอำเภอ | I10: Myset | J10: Self-Support | K10: 60 | L10: 72 | M10: 14.326589 | N10: 99.667238 | O10: 244359 | P10: 244373 | Q10: 4 | S10: =IF(P10<>"", "Complete", IF(O10<>"", "In progress", "")) -> Complete
A11: 4 | B11: ที่ว่าการอำเภอเขาสวนกวาง | C11: คำม่วง | D11: เขาสวนกวาง | E11: ขอนแก่น | F11: เขต 6 (ขอนแก่น) | G11: ภาคตะวันออกเฉียงเหนือ | H11: ที่ว่าการอำเภอ | I11: Myset | J11: Self-Support | K11: 60 | L11: 186 | M11: 16.859712 | N11: 102.86091 | O11: 244359 | P11: 244373 | Q11: 4 | S11: =IF(P11<>"", "Complete", IF(O11<>"", "In progress", "")) -> Complete
A12: 5 | B12: ที่ว่าการอำเภอวังน้ำเขียว | C12: วังน้ำเขียว | D12: วังน้ำเขียว | E12: นครราชสีมา | F12: เขต 16 (บุรีรัมย์) | G12: ภาคตะวันออกเฉียงเหนือ | H12: ที่ว่าการอำเภอ | I12: Myset | J12: Self-Support | K12: 60 | L12: 417 | M12: 14.417371 | N12: 101.84991 | O12: 244359 | P12: 244373 | Q12: 4 | S12: =IF(P12<>"", "Complete", IF(O12<>"", "In progress", "")) -> Complete
A13: 6 | B13: ที่ว่าการอำเภอเขาคิชฌกูฏ | C13: พลวง | D13: เขาคิชฌกูฏ | E13: จันทบุรี | F13: เขต 5 (จันทบุรี) | G13: ภาคตะวันออก | H13: ที่ว่าการอำเภอ | I13: Myset | J13: Self-Support | K13: 60 | L13: 20 | M13: 12.80444 | N13: 102.11464 | O13: 244370 | P13: 244385 | S13: Complete
A14: 7 | B14: ที่ว่าการอำเภอย่านตาขาว | C14: ย่านตาขาว | D14: ย่านตาขาว | E14: ตรัง | F14: เขต 9 (ส่วนแยกนครศรีธรรมราช) | G14: ภาคใต้ | H14: ที่ว่าการอำเภอ | I14: P&S | J14: Self-Support | K14: 60 | L14: 23 | M14: 7.385692 | N14: 99.666228 | O14: 244359 | P14: 244373 | Q14: 4 | S14: =IF(P14<>"", "Complete", IF(O14<>"", "In progress", "")) -> Complete
A15: 8 | B15: ที่ว่าการอำเภอหัวไทร | C15: หัวไทร | D15: หัวไทร | E15: นครศรีธรรมราช | F15: เขต 9 (ส่วนแยกนครศรีธรรมราช) | G15: ภาคใต้ | H15: ที่ว่าการอำเภอ | I15: P&S | J15: Self-Support | K15: 60 | L15: 11 | M15: 8.04059 | N15: 100.27467 | O15: 244370 | P15: 244394 | S15: Complete
A16: 9 | B16: BS หนองนกแก้ว | C16: หนองนกแก้ว | D16: เลาขวัญ | E16: กาญจนบุรี | F16: เขต 11 (เพชรบุรี) | G16: ภาคตะวันตก | H16: อบต. | I16: Myset | J16: Self-Support | K16: 60 | L16: 72 | M16: 14.514783 | N16: 99.709059 | O16: 244359 | P16: 244373 | Q16: 4 | S16: =IF(P16<>"", "Complete", IF(O16<>"", "In progress", "")) -> Complete
A17: 10 | B17: BS ปางใหม่พัฒนา | C17: ปางตาไว | D17: ปางศิลาทอง | E17: กำแพงเพชร | F17: เขต 3 (ส่วนแยกตาก) | G17: ภาคเหนือ | H17: ที่ทำการกองทุนหมู่บ้าน (กทบ.) | I17: P&S | J17: Self-Support | K17: 60 | L17: 155 | M17: 15.993741 | N17: 99.364571 | O17: 244361 | P17: 244375 | Q17: 4 | S17: =IF(P17<>"", "Complete", IF(O17<>"", "In progress", "")) -> Complete
A18: 11 | B18: BS ศรีสุขสำราญ | C18: ศรีสุขสำราญ | D18: อุบลรัตน์ | E18: ขอนแก่น | F18: เขต 6 (ขอนแก่น) | G18: ภาคตะวันออกเฉียงเหนือ | H18: อบต. | I18: Myset | J18: Self-Support | K18: 60 | L18: 200 | M18: 16.919524 | N18: 102.72752 | O18: 244363 | P18: 244384 | S18: =IF(P18<>"", "Complete", IF(O18<>"", "In progress", "")) -> Complete
A19: 12 | B19: BS คลองพลู | C19: คลองพลู | D19: เขาคิชฌกูฎ | E19: จันทบุรี | F19: เขต 5 (จันทบุรี) | G19: ภาคตะวันออก | H19: ทต. | I19: Myset | J19: Self-Support | K19: 60 | L19: 43 | M19: 12.935094 | N19: 102.05857 | O19: 244359 | P19: 244374 | S19: =IF(P19<>"", "Complete", IF(O19<>"", "In progress", "")) -> Complete
A20: 13 | B20: BS คลองป่าหมู | C20: วังกะทะ | D20: ปากช่อง | E20: นครราชสีมา | F20: เขต 16 (บุรีรัมย์) | G20: ภาคตะวันออกเฉียงเหนือ | H20: ศาลาประชาคม | I20: Myset | J20: Self-Support | K20: 60 | L20: 426 | M20: 14.480402 | N20: 101.72657 | O20: 244361 | P20: 244374 | S20: =IF(P20<>"", "Complete", IF(O20<>"", "In progress", "")) -> Complete
A21: 14 | B21: BS วังงิ้ว | C21: วังงิ้ว | D21: ดงเจริญ | E21: พิจิตร | F21: เขต 3 (พิษณุโลก) | G21: ภาคเหนือ | H21: อบต. | I21: P&S | J21: Self-Support | K21: 60 | L21: 74 | M21: 16.016102 | N21: 100.732560 | O21: 13/1/2569 | P21: 244393 | S21: =IF(P21<>"", "Complete", IF(O21<>"", "In progress", "")) -> Complete
A22: 15 | B22: BS ช่อง | C22: ช่อง | D22: นาโยง | E22: ตรัง | F22: เขต 9 (ส่วนแยกนครศรีธรรมราช) | G22: ภาคใต้ | H22: อบต. | I22: P&S | J22: Self-Support | K22: 60 | L22: 55 | M22: 7.52427 | N22: 99.75881 | O22: 244425 | S22: =IF(P22<>"", "Complete", IF(O22<>"", "In progress", "")) -> In progress
A23: 16 | B23: BS วัดบางอุดม | C23: ขนาบนาก | D23: ปากพนัง | E23: นครศรีธรรมราช | F23: เขต 9 (ส่วนแยกนครศรีธรรมราช) | G23: ภาคใต้ | H23: วัด | I23: P&S | J23: Self-Support | K23: 60 | L23: 10 | M23: 8.20462 | N23: 100.25501 | S23: =IF(P23<>"", "Complete", IF(O23<>"", "In progress", ""))

Sheet เสา 9,18,30
A1: โครงการเพิ่มประสิทธิภาพระบบโครงข่ายสื่อสารด้วยอุปกรณ์ทวนสัญญาณผ่านคลื่นความถี่สูง (SHF) เพื่อสนับสนุนการปฏิบัติราชการและแก้ไขปัญหาให้กับประชาชนในพื้นที่ห่างไกล สัญญาเลขที่ 8680228 ลงวันที่ 23 กรกฎาคม 2568
AZ2: 31 มี.ค.69
A3: แผนการเข้าดำเนินงานสำรวจและติดตั้งเสาสัญญาณ ในพื้นที่ 10 จังหวัด
A5: ลำดับ | B5: สถานที่ติดตั้ง | C5: ตำบล | D5: อำเภอ | E5: จังหวัด | F5: เขตพื้นที่รับผิดชอบศูนย์สื่อสารกรมการปกครองเขต | G5: ภาค | H5: พื้นที่ | I5: พื้นที่ใหม่ | J5: วาระผู้ใหญ่บ้าน | K5: ผู้รับเหมาเสา | L5: ชนิดของเสา | M5: ความสูงเสา (เมตร) | N5: Sea level (เมตร) | O5: Latitude | P5: Longitude | Q5: สำรวจพื้นที่สำหรับติดตั้งเสาสัญญาณ | AD5: โครงสร้างเสาสัญญาณ | AU5: วาระดำรงตำแหน่ง (กพ) | AV5: ผญบ. หยุดปฏิบัติหน้าที่ | AW5: ไม่ต้องการมิเตอร์ | AX5: ติดตั้งฐานรากและโครงสร้างเสาระบบวิทยุสื่อสาร | BJ5: ส่งมอบงาน | BL5: รายละเอียดที่ต้องแก้ไขงาน | BM5: ผู้ควบคุมงาน
Q6: สำรวจจุดติดตั้ง | U6: ทดสอบดิน (Soil Test) | Y6: Detail Design Drawing | AC6: จัดส่งผลสำรวจดินและ แบบก่อสร้าง | AD6: แบบโครงสร้างเสาสัญญาณ | AG6: ตัวอย่างโครงสร้างเสาสัญญาณ | AJ6: ผลิตโครงสร้างเสาสัญญาณ | AN6: ติดตั้งฐานราก | BA6: ตรวจสอบความพร้อมก่อนส่งมอบงาน | BC6: Report | BD6: Red mark Drawing | BG6: As-Built Drawing
Q7: Plan | R7: Actual | S7: Status | T7: Report | U7: Plan | V7: Actual | W7: Status | X7: Report | Y7: Plan | Z7: Actual | AA7: Status | AB7: Report | AD7: ออกแบบโครงสร้างเสา | AE7: ส่งแบบขออนุมัติ | AF7: Status | AG7: ผลิตตัวอย่างโครงสร้างเสาเสร็จ | AH7: ตรวจสอบตัวอย่างโครงสร้างเสาโดยคณะกรรมการฯ | AI7: Status | AJ7: Plan | AK7: Actual | AL7: Status | AM7: เบิกโครงสร้างเสาสัญญาณ | AN7: Plan Start | AO7: Plan Finish | AP7: Actual Start | AQ7: Actual Finish | AR7: จำนวนแท่งกราวด์ | AS7: ค่ากราวด์ <= 5 Ohm | AT7: Status | AX7: ปฏิบัติ (เริ่ม) | AY7: ปฏิบัติ (เสร็จ) | AZ7: สถานะ | BA7: ตรวจสอบความตั้งตรง และค่าขันน็อต | BB7: ปรับระดับพื้นที่ก่อสร้างคืนสู่สภาพเดิม | BD7: Plan | BE7: Actual | BF7: Status | BG7: Plan | BH7: Actual | BI7: Status | BJ7: เอกสารประกอบการส่งมอบงาน | BK7: Status
A9: =SUBTOTAL(3,A10:A190) -> 20 | B9: =SUBTOTAL(3,B10:B190) -> 20 | C9: =SUBTOTAL(3,C10:C190) -> 20 | D9: =SUBTOTAL(3,D10:D190) -> 20 | E9: =SUBTOTAL(3,E10:E190) -> 20 | F9: =SUBTOTAL(3,F10:F190) -> 20 | G9: =SUBTOTAL(3,G10:G190) -> 20 | H9: =SUBTOTAL(3,H10:H190) -> 20 | ... BM9: =SUBTOTAL(3,BM10:BM190) -> 0
A10: 1 | B10: หมู่ 13 หนองจิกน้ำดำ | C10: ทุ่งกระบ่ำ | D10: เลาขวัญ | E10: กาญจนบุรี | F10: เขต 11 (เพชรบุรี) | G10: ภาคตะวันตก | H10: ที่ทำการบ้าน ผญบ. | J10: 5 ปี | K10: Myset | L10: New Self-Support | M10: 9 | N10: 114 | O10: 14.601033 | P10: 99.615861 | Q10: 15/09/2568 | R10: 15/09/2568 | S10: =IF(R10<>"", "Complete", IF(Q10<>"", "In progress", "")) -> Complete | T10: Complete | U10: 19/11/2568 | V10: 19/11/2568 | W10: =IF( AND( OR(M10=9,M10=18,M10=30), OR(G10="ภาคเหนือ",G10="ภาคใต้",G10="ภาคตะวันออก",G10="ภาคตะวันตก",G10="ภาคตะวันออกเฉียงเหนือ") ), IF(V10<>"","Complete",IF(U10<>"","In progress","")), "-" ) -> Complete | X10: 28/11/2568 | Y10: 15/10/2568 | AA10: =IF(Z10<>"", "Complete", IF(Y10<>"", "In progress", "")) -> In progress | AD10: 15/09/2568 | AE10: 244145 | AF10: =IF(AE10<>"", "Complete", IF(AD10<>"", "In progress", "")) -> Complete | AG10: 244206 | AH10: 15/10/2568 | AI10: =IF(AH10<>"", "Complete", IF(AG10<>"", "In progress", "")) -> Complete | AJ10: 22/01/2569 | AL10: =IF(AK10<>"", "Complete", IF(AJ10<>"", "In progress", "")) -> In progress | AT10: =IF(AQ10<>"", "Complete", IF(AP10<>"", "In progress", "")) | AX10: 244407 | AY10: 244432 | AZ10: =IF(AY10<>"", "Complete", IF(AX10<>"", "In progress", "")) -> Complete | BF10: =IF(BE10<>"", "Complete", IF(BD10<>"", "In progress", "")) | BI10: =IF(BH10<>"", "Complete", IF(BG10<>"", "In progress", ""))
A11: 2 | B11: หมู่ 6 สี่กั๊ก | C11: ทุ่งกระบ่ำ | D11: เลาขวัญ | E11: กาญจนบุรี | F11: เขต 11 (เพชรบุรี) | G11: ภาคตะวันตก | H11: ที่ทำการบ้าน ผญบ. | J11: 9 ปี 8 เดือน | K11: Myset | L11: New Self-Support | M11: 9 | N11: 90 | O11: 14.588587 | P11: 99.638117 | Q11: 15/09/2568 | R11: 15/09/2568 | S11: =IF(R11<>"", "Complete", IF(Q11<>"", "In progress", "")) -> Complete | T11: Complete | U11: 19/11/2568 | V11: 19/11/2568 | W11: =IF( AND( OR(M11=9,M11=18,M11=30), OR(G11="ภาคเหนือ",G11="ภาคใต้",G11="ภาคตะวันออก",G11="ภาคตะวันตก",G11="ภาคตะวันออกเฉียงเหนือ") ), IF(V11<>"","Complete",IF(U11<>"","In progress","")), "-" ) -> Complete | X11: 28/11/2568 | Y11: 15/10/2568 | AA11: =IF(Z11<>"", "Complete", IF(Y11<>"", "In progress", "")) -> In progress | AD11: 15/09/2568 | AE11: 244145 | AF11: =IF(AE11<>"", "Complete", IF(AD11<>"", "In progress", "")) -> Complete | AG11: 244206 | AH11: 15/10/2568 | AI11: =IF(AH11<>"", "Complete", IF(AG11<>"", "In progress", "")) -> Complete | AJ11: 22/01/2569 | AL11: =IF(AK11<>"", "Complete", IF(AJ11<>"", "In progress", "")) -> In progress | AT11: =IF(AQ11<>"", "Complete", IF(AP11<>"", "In progress", "")) | AX11: 244407 | AY11: 244432 | AZ11: =IF(AY11<>"", "Complete", IF(AX11<>"", "In progress", "")) -> Complete | BF11: =IF(BE11<>"", "Complete", IF(BD11<>"", "In progress", "")) | BI11: =IF(BH11<>"", "Complete", IF(BG11<>"", "In progress", ""))
A12: 3 | B12: หมู่ 7 หนองปลิง | C12: ทุ่งกระบ่ำ | D12: เลาขวัญ | E12: กาญจนบุรี | F12: เขต 11 (เพชรบุรี) | G12: ภาคตะวันตก | H12: ที่ทำการบ้าน ผญบ. | J12: 1 ปี 10 เดือน | K12: Myset | L12: New Self-Support | M12: 9 | N12: 104 | O12: 14.567454 | P12: 99.634531 | Q12: 15/09/2568 | R12: 15/09/2568 | S12: =IF(R12<>"", "Complete", IF(Q12<>"", "In progress", "")) -> Complete | T12: Complete | U12: 19/11/2568 | V12: 19/11/2568 | W12: =IF( AND( OR(M12=9,M12=18,M12=30), OR(G12="ภาคเหนือ",G12="ภาคใต้",G12="ภาคตะวันออก",G12="ภาคตะวันตก",G12="ภาคตะวันออกเฉียงเหนือ") ), IF(V12<>"","Complete",IF(U12<>"","In progress","")), "-" ) -> Complete | X12: 28/11/2568 | Y12: 15/10/2568 | AA12: =IF(Z12<>"", "Complete", IF(Y12<>"", "In progress", "")) -> In progress | AD12: 15/09/2568 | AE12: 244145 | AF12: =IF(AE12<>"", "Complete", IF(AD12<>"", "In progress", "")) -> Complete | AG12: 244206 | AH12: 15/10/2568 | AI12: =IF(AH12<>"", "Complete", IF(AG12<>"", "In progress", "")) -> Complete | AJ12: 22/01/2569 | AL12: =IF(AK12<>"", "Complete", IF(AJ12<>"", "In progress", "")) -> In progress | AT12: =IF(AQ12<>"", "Complete", IF(AP12<>"", "In progress", "")) | AX12: 244407 | AY12: 244433 | AZ12: =IF(AY12<>"", "Complete", IF(AX12<>"", "In progress", "")) -> Complete | BF12: =IF(BE12<>"", "Complete", IF(BD12<>"", "In progress", "")) | BI12: =IF(BH12<>"", "Complete", IF(BG12<>"", "In progress", ""))
A13: 4 | B13: หมู่ 8 ชัฎดงพลับ | C13: ทุ่งกระบ่ำ | D13: เลาขวัญ | E13: กาญจนบุรี | F13: เขต 11 (เพชรบุรี) | G13: ภาคตะวันตก | H13: ที่ทำการบ้าน ผญบ. | J13: 18 ปี9 เดือน | K13: Myset | L13: New Self-Support | M13: 9 | N13: 86 | O13: 14.625292 | P13: 99.652235 | Q13: 15/09/2568 | R13: 15/09/2568 | S13: =IF(R13<>"", "Complete", IF(Q13<>"", "In progress", "")) -> Complete | T13: Complete | U13: 19/11/2568 | V13: 19/11/2568 | W13: =IF( AND( OR(M13=9,M13=18,M13=30), OR(G13="ภาคเหนือ",G13="ภาคใต้",G13="ภาคตะวันออก",G13="ภาคตะวันตก",G13="ภาคตะวันออกเฉียงเหนือ") ), IF(V13<>"","Complete",IF(U13<>"","In progress","")), "-" ) -> Complete | X13: 28/11/2568 | Y13: 15/10/2568 | AA13: =IF(Z13<>"", "Complete", IF(Y13<>"", "In progress", "")) -> In progress | AD13: 15/09/2568 | AE13: 244145 | AF13: =IF(AE13<>"", "Complete", IF(AD13<>"", "In progress", "")) -> Complete | AG13: 244206 | AH13: 15/10/2568 | AI13: =IF(AH13<>"", "Complete", IF(AG13<>"", "In progress", "")) -> Complete | AJ13: 22/01/2569 | AL13: =IF(AK13<>"", "Complete", IF(AJ13<>"", "In progress", "")) -> In progress | AT13: =IF(AQ13<>"", "Complete", IF(AP13<>"", "In progress", "")) | AX13: 244407 | AY13: 244432 | AZ13: =IF(AY13<>"", "Complete", IF(AX13<>"", "In progress", "")) -> Complete | BF13: =IF(BE13<>"", "Complete", IF(BD13<>"", "In progress", "")) | BI13: =IF(BH13<>"", "Complete", IF(BG13<>"", "In progress", ""))
A14: 5 | B14: หมู่ 2 หนองเค็ด | C14: หนองนกแก้ว | D14: เลาขวัญ | E14: กาญจนบุรี | F14: เขต 11 (เพชรบุรี) | G14: ภาคตะวันตก | H14: ที่ทำการบ้าน ผญบ. | J14: 7 ปี 9 เดือน | K14: Myset | L14: New Self-Support | M14: 9 | N14: 105 | O14: 14.477975 | P14: 99.653895 | Q14: 15/09/2568 | R14: 15/09/2568 | S14: =IF(R14<>"", "Complete", IF(Q14<>"", "In progress", "")) -> Complete | T14: Complete | U14: 19/11/2568 | V14: 19/11/2568 | W14: =IF( AND( OR(M14=9,M14=18,M14=30), OR(G14="ภาคเหนือ",G14="ภาคใต้",G14="ภาคตะวันออก",G14="ภาคตะวันตก",G14="ภาคตะวันออกเฉียงเหนือ") ), IF(V14<>"","Complete",IF(U14<>"","In progress","")), "-" ) -> Complete | X14: 28/11/2568 | Y14: 15/10/2568 | AA14: =IF(Z14<>"", "Complete", IF(Y14<>"", "In progress", "")) -> In progress | AD14: 15/09/2568 | AE14: 244145 | AF14: =IF(AE14<>"", "Complete", IF(AD14<>"", "In progress", "")) -> Complete | AG14: 244206 | AH14: 15/10/2568 | AI14: =IF(AH14<>"", "Complete", IF(AG14<>"", "In progress", "")) -> Complete | AJ14: 22/01/2569 | AL14: =IF(AK14<>"", "Complete", IF(AJ14<>"", "In progress", "")) -> In progress | AT14: =IF(AQ14<>"", "Complete", IF(AP14<>"", "In progress", "")) | AX14: 244381 | AY14: 244436 | AZ14: =IF(AY14<>"", "Complete", IF(AX14<>"", "In progress", "")) -> Complete | BF14: =IF(BE14<>"", "Complete", IF(BD14<>"", "In progress", "")) | BI14: =IF(BH14<>"", "Complete", IF(BG14<>"", "In progress", ""))
A15: 6 | B15: หมู่ 4 หนองจั่น | C15: หนองนกแก้ว | D15: เลาขวัญ | E15: กาญจนบุรี | F15: เขต 11 (เพชรบุรี) | G15: ภาคตะวันตก | H15: ที่ทำการบ้าน ผญบ. | J15: 16 ปี 6 เดือน | K15: Myset | L15: New Self-Support | M15: 9 | N15: 106 | O15: 14.532685 | P15: 99.649881 | Q15: 15/09/2568 | R15: 15/09/2568 | S15: =IF(R15<>"", "Complete", IF(Q15<>"", "In progress", "")) -> Complete | T15: Complete | U15: 19/11/2568 | V15: 19/11/2568 | W15: =IF( AND( OR(M15=9,M15=18,M15=30), OR(G15="ภาคเหนือ",G15="ภาคใต้",G15="ภาคตะวันออก",G15="ภาคตะวันตก",G15="ภาคตะวันออกเฉียงเหนือ") ), IF(V15<>"","Complete",IF(U15<>"","In progress","")), "-" ) -> Complete | X15: 28/11/2568 | Y15: 15/10/2568 | AA15: =IF(Z15<>"", "Complete", IF(Y15<>"", "In progress", "")) -> In progress | AD15: 15/09/2568 | AE15: 244145 | AF15: =IF(AE15<>"", "Complete", IF(AD15<>"", "In progress", "")) -> Complete | AG15: 244206 | AH15: 15/10/2568 | AI15: =IF(AH15<>"", "Complete", IF(AG15<>"", "In progress", "")) -> Complete | AJ15: 22/01/2569 | AL15: =IF(AK15<>"", "Complete", IF(AJ15<>"", "In progress", "")) -> In progress | AT15: =IF(AQ15<>"", "Complete", IF(AP15<>"", "In progress", "")) | AX15: 244407 | AY15: 244433 | AZ15: =IF(AY15<>"", "Complete", IF(AX15<>"", "In progress", "")) -> Complete | BF15: =IF(BE15<>"", "Complete", IF(BD15<>"", "In progress", "")) | BI15: =IF(BH15<>"", "Complete", IF(BG15<>"", "In progress", ""))
A16: 7 | B16: หมู่ 5 หนองขบ | C16: หนองนกแก้ว | D16: เลาขวัญ | E16: กาญจนบุรี | F16: เขต 11 (เพชรบุรี) | G16: ภาคตะวันตก | H16: ที่ทำการบ้าน ผญบ. | J16: 19 ปี | K16: Myset | L16: New Self-Support | M16: 9 | N16: 87 | O16: 14.494989 | P16: 99.673001 | Q16: 15/09/2568 | R16: 15/09/2568 | S16: =IF(R16<>"", "Complete", IF(Q16<>"", "In progress", "")) -> Complete | T16: Complete | U16: 19/11/2568 | V16: 19/11/2568 | W16: =IF( AND( OR(M16=9,M16=18,M16=30), OR(G16="ภาคเหนือ",G16="ภาคใต้",G16="ภาคตะวันออก",G16="ภาคตะวันตก",G16="ภาคตะวันออกเฉียงเหนือ") ), IF(V16<>"","Complete",IF(U16<>"","In progress","")), "-" ) -> Complete | X16: 28/11/2568 | Y16: 15/10/2568 | AA16: =IF(Z16<>"", "Complete", IF(Y16<>"", "In progress", "")) -> In progress | AD16: 15/09/2568 | AE16: 244145 | AF16: =IF(AE16<>"", "Complete", IF(AD16<>"", "In progress", "")) -> Complete | AG16: 244206 | AH16: 15/10/2568 | AI16: =IF(AH16<>"", "Complete", IF(AG16<>"", "In progress", "")) -> Complete | AJ16: 22/01/2569 | AL16: =IF(AK16<>"", "Complete", IF(AJ16<>"", "In progress", "")) -> In progress | AT16: =IF(AQ16<>"", "Complete", IF(AP16<>"", "In progress", "")) | AX16: 244381 | AY16: 244434 | AZ16: =IF(AY16<>"", "Complete", IF(AX16<>"", "In progress", "")) -> Complete | BF16: =IF(BE16<>"", "Complete", IF(BD16<>"", "In progress", "")) | BI16: =IF(BH16<>"", "Complete", IF(BG16<>"", "In progress", ""))
A17: 8 | B17: หมู่ 9 หนองข่อย | C17: หนองนกแก้ว | D17: เลาขวัญ | E17: กาญจนบุรี | F17: เขต 11 (เพชรบุรี) | G17: ภาคตะวันตก | H17: ที่ทำการบ้าน ผญบ. | J17: 6 ปี 8 เดือน | K17: Myset | L17: New Self-Support | M17: 9 | N17: 132 | O17: 14.51521 | P17: 99.633163 | Q17: 15/09/2568 | R17: 15/09/2568 | S17: =IF(R17<>"", "Complete", IF(Q17<>"", "In progress", "")) -> Complete | T17: Complete | U17: 19/11/2568 | V17: 19/11/2568 | W17: =IF( AND( OR(M17=9,M17=18,M17=30), OR(G17="ภาคเหนือ",G17="ภาคใต้",G17="ภาคตะวันออก",G17="ภาคตะวันตก",G17="ภาคตะวันออกเฉียงเหนือ") ), IF(V17<>"","Complete",IF(U17<>"","In progress","")), "-" ) -> Complete | X17: 28/11/2568 | Y17: 15/10/2568 | AA17: =IF(Z17<>"", "Complete", IF(Y17<>"", "In progress", "")) -> In progress | AD17: 15/09/2568 | AE17: 244145 | AF17: =IF(AE17<>"", "Complete", IF(AD17<>"", "In progress", "")) -> Complete | AG17: 244206 | AH17: 15/10/2568 | AI17: =IF(AH17<>"", "Complete", IF(AG17<>"", "In progress", "")) -> Complete | AJ17: 22/01/2569 | AL17: =IF(AK17<>"", "Complete", IF(AJ17<>"", "In progress", "")) -> In progress | AT17: =IF(AQ17<>"", "Complete", IF(AP17<>"", "In progress", "")) | AX17: 244407 | AY17: 244433 | AZ17: =IF(AY17<>"", "Complete", IF(AX17<>"", "In progress", "")) -> Complete | BF17: =IF(BE17<>"", "Complete", IF(BD17<>"", "In progress", "")) | BI17: =IF(BH17<>"", "Complete", IF(BG17<>"", "In progress", ""))
A18: 9 | B18: หมู่ 10 หนองมะสังข์ | C18: หนองประดู่ | D18: เลาขวัญ | E18: กาญจนบุรี | F18: เขต 11 (เพชรบุรี) | G18: ภาคตะวันตก | H18: ที่ทำการบ้าน ผญบ. | J18: 22 ปี 11 เดือน | K18: Myset | L18: New Self-Support | M18: 9 | N18: 73 | O18: 14.486867 | P18: 99.695016 | Q18: 15/09/2568 | R18: 15/09/2568 | S18: =IF(R18<>"", "Complete", IF(Q18<>"", "In progress", "")) -> Complete | T18: Complete | U18: 19/11/2568 | V18: 19/11/2568 | W18: =IF( AND( OR(M18=9,M18=18,M18=30), OR(G18="ภาคเหนือ",G18="ภาคใต้",G18="ภาคตะวันออก",G18="ภาคตะวันตก",G18="ภาคตะวันออกเฉียงเหนือ") ), IF(V18<>"","Complete",IF(U18<>"","In progress","")), "-" ) -> Complete | X18: 28/11/2568 | Y18: 15/10/2568 | AA18: =IF(Z18<>"", "Complete", IF(Y18<>"", "In progress", "")) -> In progress | AD18: 15/09/2568 | AE18: 244145 | AF18: =IF(AE18<>"", "Complete", IF(AD18<>"", "In progress", "")) -> Complete | AG18: 244206 | AH18: 15/10/2568 | AI18: =IF(AH18<>"", "Complete", IF(AG18<>"", "In progress", "")) -> Complete | AJ18: 22/01/2569 | AL18: =IF(AK18<>"", "Complete", IF(AJ18<>"", "In progress", "")) -> In progress | AT18: =IF(AQ18<>"", "Complete", IF(AP18<>"", "In progress", "")) | AX18: 244381 | AY18: 244434 | AZ18: =IF(AY18<>"", "Complete", IF(AX18<>"", "In progress", "")) -> Complete | BF18: =IF(BE18<>"", "Complete", IF(BD18<>"", "In progress", "")) | BI18: =IF(BH18<>"", "Complete", IF(BG18<>"", "In progress", ""))
A19: 10 | B19: หมู่ 11 หนองตาเกิด | C19: หนองประดู่ | D19: เลาขวัญ | E19: กาญจนบุรี | F19: เขต 11 (เพชรบุรี) | G19: ภาคตะวันตก | H19: ที่ทำการบ้าน ผญบ. | J19: 10 ปี | K19: Myset | L19: New Self-Support | M19: 9 | N19: 42 | O19: 14.448948 | P19: 99.723167 | Q19: 15/09/2568 | R19: 15/09/2568 | S19: =IF(R19<>"", "Complete", IF(Q19<>"", "In progress", "")) -> Complete | T19: Complete | U19: 19/11/2568 | V19: 19/11/2568 | W19: =IF( AND( OR(M19=9,M19=18,M19=30), OR(G19="ภาคเหนือ",G19="ภาคใต้",G19="ภาคตะวันออก",G19="ภาคตะวันตก",G19="ภาคตะวันออกเฉียงเหนือ") ), IF(V19<>"","Complete",IF(U19<>"","In progress","")), "-" ) -> Complete | X19: 28/11/2568 | Y19: 15/10/2568 | AA19: =IF(Z19<>"", "Complete", IF(Y19<>"", "In progress", "")) -> In progress | AD19: 15/09/2568 | AE19: 244145 | AF19: =IF(AE19<>"", "Complete", IF(AD19<>"", "In progress", "")) -> Complete | AG19: 244206 | AH19: 15/10/2568 | AI19: =IF(AH19<>"", "Complete", IF(AG19<>"", "In progress", "")) -> Complete | AJ19: 22/01/2569 | AL19: =IF(AK19<>"", "Complete", IF(AJ19<>"", "In progress", "")) -> In progress | AT19: =IF(AQ19<>"", "Complete", IF(AP19<>"", "In progress", "")) | AX19: 244398 | AY19: 244436 | AZ19: =IF(AY19<>"", "Complete", IF(AX19<>"", "In progress", "")) -> Complete | BF19: =IF(BE19<>"", "Complete", IF(BD19<>"", "In progress", "")) | BI19: =IF(BH19<>"", "Complete", IF(BG19<>"", "In progress", ""))
A20: 11 | B20: หมู่ 3 ตลุงเหนือ | C20: หนองประดู่ | D20: เลาขวัญ | E20: กาญจนบุรี | F20: เขต 11 (เพชรบุรี) | G20: ภาคตะวันตก | H20: ที่ทำการบ้าน ผญบ. | J20: 5 ปี | K20: Myset | L20: New Self-Support | M20: 9 | N20: 40 | O20: 14.421935 | P20: 99.727385 | Q20: 15/09/2568 | R20: 15/09/2568 | S20: =IF(R20<>"", "Complete", IF(Q20<>"", "In progress", "")) -> Complete | T20: Complete | U20: 19/11/2568 | V20: 19/11/2568 | W20: =IF( AND( OR(M20=9,M20=18,M20=30), OR(G20="ภาคเหนือ",G20="ภาคใต้",G20="ภาคตะวันออก",G20="ภาคตะวันตก",G20="ภาคตะวันออกเฉียงเหนือ") ), IF(V20<>"","Complete",IF(U20<>"","In progress","")), "-" ) -> Complete | X20: 28/11/2568 | Y20: 15/10/2568 | AA20: =IF(Z20<>"", "Complete", IF(Y20<>"", "In progress", "")) -> In progress | AD20: 15/09/2568 | AE20: 244145 | AF20: =IF(AE20<>"", "Complete", IF(AD20<>"", "In progress", "")) -> Complete | AG20: 244206 | AH20: 15/10/2568 | AI20: =IF(AH20<>"", "Complete", IF(AG20<>"", "In progress", "")) -> Complete | AJ20: 22/01/2569 | AL20: =IF(AK20<>"", "Complete", IF(AJ20<>"", "In progress", "")) -> In progress | AT20: =IF(AQ20<>"", "Complete", IF(AP20<>"", "In progress", "")) | AX20: 244398 | AY20: 244436 | AZ20: =IF(AY20<>"", "Complete", IF(AX20<>"", "In progress", "")) -> Complete | BF20: =IF(BE20<>"", "Complete", IF(BD20<>"", "In progress", "")) | BI20: =IF(BH20<>"", "Complete", IF(BG20<>"", "In progress", ""))
A21: 12 | B21: หมู่ 5 หนองปรือ | C21: หนองประดู่ | D21: เลาขวัญ | E21: กาญจนบุรี | F21: เขต 11 (เพชรบุรี) | G21: ภาคตะวันตก | H21: ที่ทำการบ้าน ผญบ. | J21: 19 ปี | K21: Myset | L21: New Self-Support | M21: 9 | N21: 40 | O21: 14.435006 | P21: 99.735956 | Q21: 15/09/2568 | R21: 15/09/2568 | S21: =IF(R21<>"", "Complete", IF(Q21<>"", "In progress", "")) -> Complete | T21: Complete | U21: 19/11/2568 | V21: 19/11/2568 | W21: =IF( AND( OR(M21=9,M21=18,M21=30), OR(G21="ภาคเหนือ",G21="ภาคใต้",G21="ภาคตะวันออก",G21="ภาคตะวันตก",G21="ภาคตะวันออกเฉียงเหนือ") ), IF(V21<>"","Complete",IF(U21<>"","In progress","")), "-" ) -> Complete | X21: 28/11/2568 | Y21: 15/10/2568 | AA21: =IF(Z21<>"", "Complete", IF(Y21<>"", "In progress", "")) -> In progress | AD21: 15/09/2568 | AE21: 244145 | AF21: =IF(AE21<>"", "Complete", IF(AD21<>"", "In progress", "")) -> Complete | AG21: 244206 | AH21: 15/10/2568 | AI21: =IF(AH21<>"", "Complete", IF(AG21<>"", "In progress", "")) -> Complete | AJ21: 22/01/2569 | AL21: =IF(AK21<>"", "Complete", IF(AJ21<>"", "In progress", "")) -> In progress | AT21: =IF(AQ21<>"", "Complete", IF(AP21<>"", "In progress", "")) | AX21: 244398 | AY21: 244436 | AZ21: =IF(AY21<>"", "Complete", IF(AX21<>"", "In progress", "")) -> Complete | BF21: =IF(BE21<>"", "Complete", IF(BD21<>"", "In progress", "")) | BI21: =IF(BH21<>"", "Complete", IF(BG21<>"", "In progress", ""))
A22: 13 | B22: หมู่ 6 น้ำโจน | C22: หนองประดู่ | D22: เลาขวัญ | E22: กาญจนบุรี | F22: เขต 11 (เพชรบุรี) | G22: ภาคตะวันตก | H22: ที่ทำการบ้าน ผญบ. | J22: 9 ปี 8 เดือน | K22: Myset | L22: New Self-Support | M22: 9 | N22: 56 | O22: 14.481615 | P22: 99.745157 | Q22: 15/09/2568 | R22: 15/09/2568 | S22: =IF(R22<>"", "Complete", IF(Q22<>"", "In progress", "")) -> Complete | T22: Complete | U22: 19/11/2568 | V22: 19/11/2568 | W22: =IF( AND( OR(M22=9,M22=18,M22=30), OR(G22="ภาคเหนือ",G22="ภาคใต้",G22="ภาคตะวันออก",G22="ภาคตะวันตก",G22="ภาคตะวันออกเฉียงเหนือ") ), IF(V22<>"","Complete",IF(U22<>"","In progress","")), "-" ) -> Complete | X22: 28/11/2568 | Y22: 15/10/2568 | AA22: =IF(Z22<>"", "Complete", IF(Y22<>"", "In progress", "")) -> In progress | AD22: 15/09/2568 | AE22: 244145 | AF22: =IF(AE22<>"", "Complete", IF(AD22<>"", "In progress", "")) -> Complete | AG22: 244206 | AH22: 15/10/2568 | AI22: =IF(AH22<>"", "Complete", IF(AG22<>"", "In progress", "")) -> Complete | AJ22: 22/01/2569 | AL22: =IF(AK22<>"", "Complete", IF(AJ22<>"", "In progress", "")) -> In progress | AT22: =IF(AQ22<>"", "Complete", IF(AP22<>"", "In progress", "")) | AX22: 244398 | AY22: 244436 | AZ22: =IF(AY22<>"", "Complete", IF(AX22<>"", "In progress", "")) -> Complete | BF22: =IF(BE22<>"", "Complete", IF(BD22<>"", "In progress", "")) | BI22: =IF(BH22<>"", "Complete", IF(BG22<>"", "In progress", ""))
A23: 14 | B23: หมู่ 8 หนองแกแดง | C23: หนองประดู่ | D23: เลาขวัญ | E23: กาญจนบุรี | F23: เขต 11 (เพชรบุรี) | G23: ภาคตะวันตก | H23: ที่ทำการบ้าน กำนัน | J23: 11 ปี 4 เดือน | K23: Myset | L23: New Self-Support | M23: 9 | N23: 75 | O23: 14.446396 | P23: 99.667616 | Q23: 15/09/2568 | R23: 15/09/2568 | S23: =IF(R23<>"", "Complete", IF(Q23<>"", "In progress", "")) -> Complete | T23: Complete | U23: 19/11/2568 | V23: 19/11/2568 | W23: =IF( AND( OR(M23=9,M23=18,M23=30), OR(G23="ภาคเหนือ",G23="ภาคใต้",G23="ภาคตะวันออก",G23="ภาคตะวันตก",G23="ภาคตะวันออกเฉียงเหนือ") ), IF(V23<>"","Complete",IF(U23<>"","In progress","")), "-" ) -> Complete | X23: 28/11/2568 | Y23: 15/10/2568 | AA23: =IF(Z23<>"", "Complete", IF(Y23<>"", "In progress", "")) -> In progress | AD23: 15/09/2568 | AE23: 244145 | AF23: =IF(AE23<>"", "Complete", IF(AD23<>"", "In progress", "")) -> Complete | AG23: 244206 | AH23: 15/10/2568 | AI23: =IF(AH23<>"", "Complete", IF(AG23<>"", "In progress", "")) -> Complete | AJ23: 22/01/2569 | AL23: =IF(AK23<>"", "Complete", IF(AJ23<>"", "In progress", "")) -> In progress | AT23: =IF(AQ23<>"", "Complete", IF(AP23<>"", "In progress", "")) | AX23: 244381 | AY23: 244435 | AZ23: =IF(AY23<>"", "Complete", IF(AX23<>"", "In progress", "")) -> Complete | BF23: =IF(BE23<>"", "Complete", IF(BD23<>"", "In progress", "")) | BI23: =IF(BH23<>"", "Complete", IF(BG23<>"", "In progress", ""))
A24: 15 | B24: หมู่ 9 เหียงงาม | C24: หนองประดู่ | D24: เลาขวัญ | E24: กาญจนบุรี | F24: เขต 11 (เพชรบุรี) | G24: ภาคตะวันตก | H24: ที่ทำการบ้าน ผญบ. | J24: 18 ปี 7 เดือน | K24: Myset | L24: New Self-Support | M24: 9 | N24: 34 | O24: 14.406573 | P24: 99.741555 | Q24: 15/09/2568 | R24: 15/09/2568 | S24: =IF(R24<>"", "Complete", IF(Q24<>"", "In progress", "")) -> Complete | T24: Complete | U24: 19/11/2568 | V24: 19/11/2568 | W24: =IF( AND( OR(M24=9,M24=18,M24=30), OR(G24="ภาคเหนือ",G24="ภาคใต้",G24="ภาคตะวันออก",G24="ภาคตะวันตก",G24="ภาคตะวันออกเฉียงเหนือ") ), IF(V24<>"","Complete",IF(U24<>"","In progress","")), "-" ) -> Complete | X24: 28/11/2568 | Y24: 15/10/2568 | AA24: =IF(Z24<>"", "Complete", IF(Y24<>"", "In progress", "")) -> In progress | AD24: 15/09/2568 | AE24: 244145 | AF24: =IF(AE24<>"", "Complete", IF(AD24<>"", "In progress", "")) -> Complete | AG24: 244206 | AH24: 15/10/2568 | AI24: =IF(AH24<>"", "Complete", IF(AG24<>"", "In progress", "")) -> Complete | AJ24: 22/01/2569 | AL24: =IF(AK24<>"", "Complete", IF(AJ24<>"", "In progress", "")) -> In progress | AT24: =IF(AQ24<>"", "Complete", IF(AP24<>"", "In progress", "")) | AX24: 244398 | AY24: 244425 | AZ24: =IF(AY24<>"", "Complete", IF(AX24<>"", "In progress", "")) -> Complete | BF24: =IF(BE24<>"", "Complete", IF(BD24<>"", "In progress", "")) | BI24: =IF(BH24<>"", "Complete", IF(BG24<>"", "In progress", ""))
A25: 31 | B25: หมู่ 16 บ้านศรีเกษตรพัฒนา | C25: ปางมะค่า | D25: ขาณุวรลักษบุรี | E25: กำแพงเพชร | F25: เขต 3 (ส่วนแยกตาก) | G25: ภาคเหนือ | H25: ที่ทำการบ้าน ผญบ. | J25: 11 ปี | K25: P&S | L25: New Self-Support | M25: 9 | N25: 154 | O25: 15.9575 | P25: 99.38428 | Q25: 15/09/2568 | R25: 17/09/2568 | S25: =IF(R25<>"", "Complete", IF(Q25<>"", "In progress", "")) -> Complete | T25: Complete | U25: 19/11/2568 | V25: 19/11/2568 | W25: =IF( AND( OR(M25=9,M25=18,M25=30), OR(G25="ภาคเหนือ",G25="ภาคใต้",G25="ภาคตะวันออก",G25="ภาคตะวันตก",G25="ภาคตะวันออกเฉียงเหนือ") ), IF(V25<>"","Complete",IF(U25<>"","In progress","")), "-" ) -> Complete | X25: 28/11/2568 | Y25: 17/10/2568 | AA25: =IF(Z25<>"", "Complete", IF(Y25<>"", "In progress", "")) -> In progress | AD25: 15/09/2568 | AE25: 244145 | AF25: =IF(AE25<>"", "Complete", IF(AD25<>"", "In progress", "")) -> Complete | AG25: 244206 | AH25: 15/10/2568 | AI25: =IF(AH25<>"", "Complete", IF(AG25<>"", "In progress", "")) -> Complete | AJ25: 22/01/2569 | AL25: =IF(AK25<>"", "Complete", IF(AJ25<>"", "In progress", "")) -> In progress | AT25: =IF(AQ25<>"", "Complete", IF(AP25<>"", "In progress", "")) | AX25: 244402 | AY25: 244421 | AZ25: =IF(AY25<>"", "Complete", IF(AX25<>"", "In progress", "")) -> Complete | BF25: =IF(BE25<>"", "Complete", IF(BD25<>"", "In progress", "")) | BI25: =IF(BH25<>"", "Complete", IF(BG25<>"", "In progress", ""))
A26: 32 | B26: หมู่ 17 บ้านทรัพย์เจริญ | C26: ปางมะค่า | D26: ขาณุวรลักษบุรี | E26: กำแพงเพชร | F26: เขต 3 (ส่วนแยกตาก) | G26: ภาคเหนือ | H26: ศาลาประชาคม | J26: 14 ปี | K26: P&S | L26: New Self-Support | M26: 9 | N26: 168 | O26: 15.95268 | P26: 99.35793 | Q26: 15/09/2568 | R26: 17/09/2568 | S26: =IF(R26<>"", "Complete", IF(Q26<>"", "In progress", "")) -> Complete | T26: Complete | U26: 19/11/2568 | V26: 19/11/2568 | W26: =IF( AND( OR(M26=9,M26=18,M26=30), OR(G26="ภาคเหนือ",G26="ภาคใต้",G26="ภาคตะวันออก",G26="ภาคตะวันตก",G26="ภาคตะวันออกเฉียงเหนือ") ), IF(V26<>"","Complete",IF(U26<>"","In progress","")), "-" ) -> Complete | X26: 28/11/2568 | Y26: 17/10/2568 | AA26: =IF(Z26<>"", "Complete", IF(Y26<>"", "In progress", "")) -> In progress | AD26: 15/09/2568 | AE26: 244145 | AF26: =IF(AE26<>"", "Complete", IF(AD26<>"", "In progress", "")) -> Complete | AG26: 244206 | AH26: 15/10/2568 | AI26: =IF(AH26<>"", "Complete", IF(AG26<>"", "In progress", "")) -> Complete | AJ26: 22/01/2569 | AL26: =IF(AK26<>"", "Complete", IF(AJ26<>"", "In progress", "")) -> In progress | AT26: =IF(AQ26<>"", "Complete", IF(AP26<>"", "In progress", "")) | AX26: 244402 | AY26: 244421 | AZ26: =IF(AY26<>"", "Complete", IF(AX26<>"", "In progress", "")) -> Complete | BF26: =IF(BE26<>"", "Complete", IF(BD26<>"", "In progress", "")) | BI26: =IF(BH26<>"", "Complete", IF(BG26<>"", "In progress", ""))
A27: 33 | B27: หมู่ 11 บ้านมอสมบูรณ์ | C27: ปางมะค่า | D27: ขาณุวรลักษบุรี | E27: กำแพงเพชร | F27: เขต 3 (ส่วนแยกตาก) | G27: ภาคเหนือ | H27: ที่ทำการบ้าน ผญบ. | J27: 2 ปี | K27: P&S | L27: New Self-Support | M27: 9 | N27: 153.4 | O27: 15.94607 | P27: 99.41336 | Q27: 15/09/2568 | R27: 17/09/2568 | S27: =IF(R27<>"", "Complete", IF(Q27<>"", "In progress", "")) -> Complete | T27: Complete | U27: 19/11/2568 | V27: 19/11/2568 | W27: =IF( AND( OR(M27=9,M27=18,M27=30), OR(G27="ภาคเหนือ",G27="ภาคใต้",G27="ภาคตะวันออก",G27="ภาคตะวันตก",G27="ภาคตะวันออกเฉียงเหนือ") ), IF(V27<>"","Complete",IF(U27<>"","In progress","")), "-" ) -> Complete | X27: 28/11/2568 | Y27: 17/10/2568 | AA27: =IF(Z27<>"", "Complete", IF(Y27<>"", "In progress", "")) -> In progress | AD27: 15/09/2568 | AE27: 244145 | AF27: =IF(AE27<>"", "Complete", IF(AD27<>"", "In progress", "")) -> Complete | AG27: 244206 | AH27: 15/10/2568 | AI27: =IF(AH27<>"", "Complete", IF(AG27<>"", "In progress", "")) -> Complete | AJ27: 22/01/2569 | AL27: =IF(AK27<>"", "Complete", IF(AJ27<>"", "In progress", "")) -> In progress | AT27: =IF(AQ27<>"", "Complete", IF(AP27<>"", "In progress", "")) | AX27: 244402 | AY27: 244421 | AZ27: =IF(AY27<>"", "Complete", IF(AX27<>"", "In progress", "")) -> Complete | BF27: =IF(BE27<>"", "Complete", IF(BD27<>"", "In progress", "")) | BI27: =IF(BH27<>"", "Complete", IF(BG27<>"", "In progress", ""))
A28: 34 | B28: หมู่ 21 บ้านใหม่ธงชัย | C28: ปางมะค่า | D28: ขาณุวรลักษบุรี | E28: กำแพงเพชร | F28: เขต 3 (ส่วนแยกตาก) | G28: ภาคเหนือ | H28: ที่ทำการบ้าน ผญบ. | J28: 11 ปี | K28: P&S | L28: New Self-Support | M28: 9 | N28: 140 | O28: 15.93205 | P28: 99.38786 | Q28: 15/09/2568 | R28: 18/09/2568 | S28: =IF(R28<>"", "Complete", IF(Q28<>"", "In progress", "")) -> Complete | T28: Complete | U28: 19/11/2568 | V28: 19/11/2568 | W28: =IF( AND( OR(M28=9,M28=18,M28=30), OR(G28="ภาคเหนือ",G28="ภาคใต้",G28="ภาคตะวันออก",G28="ภาคตะวันตก",G28="ภาคตะวันออกเฉียงเหนือ") ), IF(V28<>"","Complete",IF(U28<>"","In progress","")), "-" ) -> Complete | X28: 28/11/2568 | Y28: 18/10/2568 | AA28: =IF(Z28<>"", "Complete", IF(Y28<>"", "In progress", "")) -> In progress | AD28: 15/09/2568 | AE28: 244145 | AF28: =IF(AE28<>"", "Complete", IF(AD28<>"", "In progress", "")) -> Complete | AG28: 244206 | AH28: 15/10/2568 | AI28: =IF(AH28<>"", "Complete", IF(AG28<>"", "In progress", "")) -> Complete | AJ28: 22/01/2569 | AL28: =IF(AK28<>"", "Complete", IF(AJ28<>"", "In progress", "")) -> In progress | AT28: =IF(AQ28<>"", "Complete", IF(AP28<>"", "In progress", "")) | AX28: 244402 | AY28: 244421 | AZ28: =IF(AY28<>"", "Complete", IF(AX28<>"", "In progress", "")) -> Complete | BF28: =IF(BE28<>"", "Complete", IF(BD28<>"", "In progress", "")) | BI28: =IF(BH28<>"", "Complete", IF(BG28<>"", "In progress", ""))
A29: 35 | B29: หมู่ 6 บ้านเกาะแก้ว | C29: ปางมะค่า | D29: ขาณุวรลักษบุรี | E29: กำแพงเพชร | F29: เขต 3 (ส่วนแยกตาก) | G29: ภาคเหนือ | H29: ที่ทำการบ้าน ผญบ. | J29: 8 ปี | K29: P&S | L29: New Self-Support | M29: 9 | N29: 129 | O29: 15.91913 | P29: 99.40145 | Q29: 15/09/2568 | R29: 17/09/2568 | S29: =IF(R29<>"", "Complete", IF(Q29<>"", "In progress", "")) -> Complete | T29: Complete | U29: 19/11/2568 | V29: 19/11/2568 | W29: =IF( AND( OR(M29=9,M29=18,M29=30), OR(G29="ภาคเหนือ",G29="ภาคใต้",G29="ภาคตะวันออก",G29="ภาคตะวันตก",G29="ภาคตะวันออกเฉียงเหนือ") ), IF(V29<>"","Complete",IF(U29<>"","In progress","")), "-" ) -> Complete | X29: 28/11/2568 | Y29: 17/10/2568 | AA29: =IF(Z29<>"", "Complete", IF(Y29<>"", "In progress", "")) -> In progress | AD29: 15/09/2568 | AE29: 244145 | AF29: =IF(AE29<>"", "Complete", IF(AD29<>"", "In progress", "")) -> Complete | AG29: 244206 | AH29: 15/10/2568 | AI29: =IF(AH29<>"", "Complete", IF(AG29<>"", "In progress", "")) -> Complete | AJ29: 22/01/2569 | AL29: =IF(AK29<>"", "Complete", IF(AJ29<>"", "In progress", "")) -> In progress | AT29: =IF(AQ29<>"", "Complete", IF(AP29<>"", "In progress", "")) | AX29: 244402 | AY29: 244421 | AZ29: =IF(AY29<>"", "Complete", IF(AX29<>"", "In progress", "")) -> Complete | BF29: =IF(BE29<>"", "Complete", IF(BD29<>"", "In progress", "")) | BI29: =IF(BH29<>"", "Complete", IF(BG29<>"", "In progress", ""))
A30: 36 | B30: หมู่ 19 บ้านศรีสมบูรณ์ | C30: ปางมะค่า | D30: ขาณุวรลักษบุรี | E30: กำแพงเพชร | F30: เขต 3 (ส่วนแยกตาก) | G30: ภาคเหนือ | H30: ศาลาประชาคม | J30: 5 เดือน | K30: P&S | L30: Self-Support | M30: 18 | N30: 125 | O30: 15.92749 | P30: 99.42296 | Q30: 15/09/2568 | R30: 18/09/2568 | S30: =IF(R30<>"", "Complete", IF(Q30<>"", "In progress", "")) -> Complete | T30: Complete | U30: 19/11/2568 | V30: 18/11/2568 | W30: =IF( AND( OR(M30=9,M30=18,M30=30), OR(G30="ภาคเหนือ",G30="ภาคใต้",G30="ภาคตะวันออก",G30="ภาคตะวันตก",G30="ภาคตะวันออกเฉียงเหนือ") ), IF(V30<>"","Complete",IF(U30<>"","In progress","")), "-" ) -> Complete | X30: 28/11/2568 | Y30: 18/10/2568 | AA30: =IF(Z30<>"", "Complete", IF(Y30<>"", "In progress", "")) -> In progress | AD30: 15/10/2568 | AE30: 21/10/2568 | AF30: =IF(AE30<>"", "Complete", IF(AD30<>"", "In progress", "")) -> Complete | AG30: 14/11/2568 | AH30: 26/11/2568 | AI30: =IF(AH30<>"", "Complete", IF(AG30<>"", "In progress", "")) -> Complete | AJ30: 244470 | AK30: 244470 | AL30: =IF(AK30<>"", "Complete", IF(AJ30<>"", "In progress", "")) -> Complete | AM30: 244684 | AN30: 15/1/2569 | AO30: 23/1/2569 | AP30: 14/1/2569 | AT30: =IF(AQ30<>"", "Complete", IF(AP30<>"", "In progress", "")) -> In progress | AX30: 244359 | AY30: 244369 | AZ30: =IF(AY30<>"", "Complete", IF(AX30<>"", "In progress", "")) -> Complete | BF30: =IF(BE30<>"", "Complete", IF(BD30<>"", "In progress", "")) | BI30: =IF(BH30<>"", "Complete", IF(BG30<>"", "In progress", "")) | BM30: นายคิรากร ดอนมูลไพร
A31: 37 | B31: หมู่ 12 มอตะแบก | C31: คลองลานพัฒนา | D31: คลองลาน | E31: กำแพงเพชร | F31: เขต 3 (ส่วนแยกตาก) | G31: ภาคเหนือ | H31: ที่ทำการบ้าน ผญบ. | J31: 4 ปี | K31: P&S | L31: New Self-Support | M31: 9 | N31: 132 | O31: 16.105584 | P31: 99.371336 | Q31: 15/09/2568 | R31: 16/09/2568 | S31: =IF(R31<>"", "Complete", IF(Q31<>"", "In progress", "")) -> Complete | T31: Complete | U31: 19/11/2568 | V31: 19/11/2568 | W31: =IF( AND( OR(M31=9,M31=18,M31=30), OR(G31="ภาคเหนือ",G31="ภาคใต้",G31="ภาคตะวันออก",G31="ภาคตะวันตก",G31="ภาคตะวันออกเฉียงเหนือ") ), IF(V31<>"","Complete",IF(U31<>"","In progress","")), "-" ) -> Complete | X31: 28/11/2568 | Y31: 16/10/2568 | AA31: =IF(Z31<>"", "Complete", IF(Y31<>"", "In progress", "")) -> In progress | AD31: 15/09/2568 | AE31: 244145 | AF31: =IF(AE31<>"", "Complete", IF(AD31<>"", "In progress", "")) -> Complete | AG31: 244206 | AH31: 15/10/2568 | AI31: =IF(AH31<>"", "Complete", IF(AG31<>"", "In progress", "")) -> Complete | AJ31: 22/01/2569 | AL31: =IF(AK31<>"", "Complete", IF(AJ31<>"", "In progress", "")) -> In progress | AT31: =IF(AQ31<>"", "Complete", IF(AP31<>"", "In progress", "")) | AX31: 244392 | AY31: 244415 | AZ31: =IF(AY31<>"", "Complete", IF(AX31<>"", "In progress", "")) -> Complete | BF31: =IF(BE31<>"", "Complete", IF(BD31<>"", "In progress", "")) | BI31: =IF(BH31<>"", "Complete", IF(BG31<>"", "In progress", ""))
A32: 38 | B32: หมู่ 4 ปากคลองลาน | C32: คลองลานพัฒนา | D32: คลองลาน | E32: กำแพงเพชร | F32: เขต 3 (ส่วนแยกตาก) | G32: ภาคเหนือ | H32: ที่ทำการบ้าน ผญบ. | J32: 4 ปี | K32: P&S | L32: New Self-Support | M32: 9 | N32: 121 | O32: 16.072842 | P32: 99.372585 | Q32: 15/09/2568 | R32: 16/09/2568 | S32: =IF(R32<>"", "Complete", IF(Q32<>"", "In progress", "")) -> Complete | T32: Complete | U32: 19/11/2568 | V32: 19/11/2568 | W32: =IF( AND( OR(M32=9,M32=18,M32=30), OR(G32="ภาคเหนือ",G32="ภาคใต้",G32="ภาคตะวันออก",G32="ภาคตะวันตก",G32="ภาคตะวันออกเฉียงเหนือ") ), IF(V32<>"","Complete",IF(U32<>"","In progress","")), "-" ) -> Complete | X32: 28/11/2568 | Y32: 16/10/2568 | AA32: =IF(Z32<>"", "Complete", IF(Y32<>"", "In progress", "")) -> In progress | AD32: 15/09/2568 | AE32: 244145 | AF32: =IF(AE32<>"", "Complete", IF(AD32<>"", "In progress", "")) -> Complete | AG32: 244206 | AH32: 15/10/2568 | AI32: =IF(AH32<>"", "Complete", IF(AG32<>"", "In progress", "")) -> Complete | AJ32: 22/01/2569 | AL32: =IF(AK32<>"", "Complete", IF(AJ32<>"", "In progress", "")) -> In progress | AT32: =IF(AQ32<>"", "Complete", IF(AP32<>"", "In progress", "")) | AX32: 244393 | AY32: 244416 | AZ32: =IF(AY32<>"", "Complete", IF(AX32<>"", "In progress", "")) -> Complete | BF32: =IF(BE32<>"", "Complete", IF(BD32<>"", "In progress", "")) | BI32: =IF(BH32<>"", "Complete", IF(BG32<>"", "In progress", ""))
A33: 39 | B33: หมู่ 1 ไพรสวรรค์ | C33: ปางตาไว | D33: ปางศิลาทอง | E33: กำแพงเพชร | F33: เขต 3 (ส่วนแยกตาก) | G33: ภาคเหนือ | H33: ที่ทำการบ้าน ผญบ. | J33: 2 ปี | K33: P&S | L33: New Self-Support | M33: 9 | N33: 112.8 | O33: 16.06211 | P33: 99.38389 | Q33: 15/09/2568 | R33: 16/09/2568 | S33: =IF(R33<>"", "Complete", IF(Q33<>"", "In progress", "")) -> Complete | T33: Complete | U33: 19/11/2568 | V33: 19/11/2568 | W33: =IF( AND( OR(M33=9,M33=18,M33=30), OR(G33="ภาคเหนือ",G33="ภาคใต้",G33="ภาคตะวันออก",G33="ภาคตะวันตก",G33="ภาคตะวันออกเฉียงเหนือ") ), IF(V33<>"","Complete",IF(U33<>"","In progress","")), "-" ) -> Complete | X33: 28/11/2568 | Y33: 16/10/2568 | AA33: =IF(Z33<>"", "Complete", IF(Y33<>"", "In progress", "")) -> In progress | AD33: 15/09/2568 | AE33: 244145 | AF33: =IF(AE33<>"", "Complete", IF(AD33<>"", "In progress", "")) -> Complete | AG33: 244206 | AH33: 15/10/2568 | AI33: =IF(AH33<>"", "Complete", IF(AG33<>"", "In progress", "")) -> Complete | AJ33: 22/01/2569 | AL33: =IF(AK33<>"", "Complete", IF(AJ33<>"", "In progress", "")) -> In progress | AT33: =IF(AQ33<>"", "Complete", IF(AP33<>"", "In progress", "")) | AX33: 244393 | AY33: 244415 | AZ33: =IF(AY33<>"", "Complete", IF(AX33<>"", "In progress", "")) -> Complete | BF33: =IF(BE33<>"", "Complete", IF(BD33<>"", "In progress", "")) | BI33: =IF(BH33<>"", "Complete", IF(BG33<>"", "In progress", ""))
A34: 40 | B34: หมู่ 10 ปางใหม่พัฒนา | C34: ปางตาไว | D34: ปางศิลาทอง | E34: กำแพงเพชร | F34: เขต 3 (ส่วนแยกตาก) | G34: ภาคเหนือ | H34: ที่ทำการบ้าน ผญบ. | J34: 4 ปี | K34: P&S | L34: New Self-Support | M34: 9 | N34: 150 | O34: 15.99509 | P34: 99.36474 | Q34: 15/09/2568 | R34: 16/09/2568 | S34: =IF(R34<>"", "Complete", IF(Q34<>"", "In progress", "")) -> Complete | T34: Complete | U34: 19/11/2568 | V34: 19/11/2568 | W34: =IF( AND( OR(M34=9,M34=18,M34=30), OR(G34="ภาคเหนือ",G34="ภาคใต้",G34="ภาคตะวันออก",G34="ภาคตะวันตก",G34="ภาคตะวันออกเฉียงเหนือ") ), IF(V34<>"","Complete",IF(U34<>"","In progress","")), "-" ) -> Complete | X34: 28/11/2568 | Y34: 16/10/2568 | AA34: =IF(Z34<>"", "Complete", IF(Y34<>"", "In progress", "")) -> In progress | AD34: 15/09/2568 | AE34: 244145 | AF34: =IF(AE34<>"", "Complete", IF(AD34<>"", "In progress", "")) -> Complete | AG34: 244206 | AH34: 15/10/2568 | AI34: =IF(AH34<>"", "Complete", IF(AG34<>"", "In progress", "")) -> Complete | AJ34: 22/01/2569 | AL34: =IF(AK34<>"", "Complete", IF(AJ34<>"", "In progress", "")) -> In progress | AT34: =IF(AQ34<>"", "Complete", IF(AP34<>"", "In progress", "")) | AX34: 244399 | AY34: 244411 | AZ34: =IF(AY34<>"", "Complete", IF(AX34<>"", "In progress", "")) -> Complete | BF34: =IF(BE34<>"", "Complete", IF(BD34<>"", "In progress", "")) | BI34: =IF(BH34<>"", "Complete", IF(BG34<>"", "In progress", ""))
A35: 41 | B35: หมู่ 2 คลองลึกพัฒนา | C35: ปางตาไว | D35: ปางศิลาทอง | E35: กำแพงเพชร | F35: เขต 3 (ส่วนแยกตาก) | G35: ภาคเหนือ | H35: ที่ทำการบ้าน ผญบ. | J35: 5 ปี | K35: P&S | L35: New Self-Support | M35: 9 | N35: 136.6 | O35: 16.03417 | P35: 99.39663 | Q35: 15/09/2568 | R35: 16/09/2568 | S35: =IF(R35<>"", "Complete", IF(Q35<>"", "In progress", "")) -> Complete | T35: Complete | U35: 19/11/2568 | V35: 19/11/2568 | W35: =IF( AND( OR(M35=9,M35=18,M35=30), OR(G35="ภาคเหนือ",G35="ภาคใต้",G35="ภาคตะวันออก",G35="ภาคตะวันตก",G35="ภาคตะวันออกเฉียงเหนือ") ), IF(V35<>"","Complete",IF(U35<>"","In progress","")), "-" ) -> Complete | X35: 28/11/2568 | Y35: 16/10/2568 | AA35: =IF(Z35<>"", "Complete", IF(Y35<>"", "In progress", "")) -> In progress | AD35: 15/09/2568 | AE35: 244145 | AF35: =IF(AE35<>"", "Complete", IF(AD35<>"", "In progress", "")) -> Complete | AG35: 244206 | AH35: 15/10/2568 | AI35: =IF(AH35<>"", "Complete", IF(AG35<>"", "In progress", "")) -> Complete | AJ35: 22/01/2569 | AL35: =IF(AK35<>"", "Complete", IF(AJ35<>"", "In progress", "")) -> In progress | AT35: =IF(AQ35<>"", "Complete", IF(AP35<>"", "In progress", "")) | AX35: 244393 | AY35: 244416 | AZ35: =IF(AY35<>"", "Complete", IF(AX35<>"", "In progress", "")) -> Complete | BF35: =IF(BE35<>"", "Complete", IF(BD35<>"", "In progress", "")) | BI35: =IF(BH35<>"", "Complete", IF(BG35<>"", "In progress", ""))
A36: 42 | B36: หมู่ 3 เพชรเจริญ | C36: ปางตาไว | D36: ปางศิลาทอง | E36: กำแพงเพชร | F36: เขต 3 (ส่วนแยกตาก) | G36: ภาคเหนือ | H36: ที่ทำการบ้าน ผญบ. | J36: 13 ปี | K36: P&S | L36: New Self-Support | M36: 9 | N36: 142 | O36: 16.02214 | P36: 99.36882 | Q36: 15/09/2568 | R36: 16/09/2568 | S36: =IF(R36<>"", "Complete", IF(Q36<>"", "In progress", "")) -> Complete | T36: Complete | U36: 19/11/2568 | V36: 19/11/2568 | W36: =IF( AND( OR(M36=9,M36=18,M36=30), OR(G36="ภาคเหนือ",G36="ภาคใต้",G36="ภาคตะวันออก",G36="ภาคตะวันตก",G36="ภาคตะวันออกเฉียงเหนือ") ), IF(V36<>"","Complete",IF(U36<>"","In progress","")), "-" ) -> Complete | X36: 28/11/2568 | Y36: 16/10/2568 | AA36: =IF(Z36<>"", "Complete", IF(Y36<>"", "In progress", "")) -> In progress | AD36: 15/09/2568 | AE36: 244145 | AF36: =IF(AE36<>"", "Complete", IF(AD36<>"", "In progress", "")) -> Complete | AG36: 244206 | AH36: 15/10/2568 | AI36: =IF(AH36<>"", "Complete", IF(AG36<>"", "In progress", "")) -> Complete | AJ36: 22/01/2569 | AL36: =IF(AK36<>"", "Complete", IF(AJ36<>"", "In progress", "")) -> In progress | AT36: =IF(AQ36<>"", "Complete", IF(AP36<>"", "In progress", "")) | AX36: 244397 | AY36: 244417 | AZ36: =IF(AY36<>"", "Complete", IF(AX36<>"", "In progress", "")) -> Complete | BF36: =IF(BE36<>"", "Complete", IF(BD36<>"", "In progress", "")) | BI36: =IF(BH36<>"", "Complete", IF(BG36<>"", "In progress", ""))
A37: 43 | B37: หมู่ 4 ปางตาไว | C37: ปางตาไว | D37: ปางศิลาทอง | E37: กำแพงเพชร | F37: เขต 3 (ส่วนแยกตาก) | G37: ภาคเหนือ | H37: ที่ทำการบ้าน ผญบ. | J37: 2 ปี | K37: P&S | L37: New Self-Support | M37: 9 | N37: 142.3 | O37: 15.99898 | P37: 99.37284 | Q37: 15/09/2568 | R37: 16/09/2568 | S37: =IF(R37<>"", "Complete", IF(Q37<>"", "In progress", "")) -> Complete | T37: Complete | U37: 19/11/2568 | V37: 19/11/2568 | W37: =IF( AND( OR(M37=9,M37=18,M37=30), OR(G37="ภาคเหนือ",G37="ภาคใต้",G37="ภาคตะวันออก",G37="ภาคตะวันตก",G37="ภาคตะวันออกเฉียงเหนือ") ), IF(V37<>"","Complete",IF(U37<>"","In progress","")), "-" ) -> Complete | X37: 28/11/2568 | Y37: 16/10/2568 | AA37: =IF(Z37<>"", "Complete", IF(Y37<>"", "In progress", "")) -> In progress | AD37: 15/09/2568 | AE37: 244145 | AF37: =IF(AE37<>"", "Complete", IF(AD37<>"", "In progress", "")) -> Complete | AG37: 244206 | AH37: 15/10/2568 | AI37: =IF(AH37<>"", "Complete", IF(AG37<>"", "In progress", "")) -> Complete | AJ37: 22/01/2569 | AL37: =IF(AK37<>"", "Complete", IF(AJ37<>"", "In progress", "")) -> In progress | AT37: =IF(AQ37<>"", "Complete", IF(AP37<>"", "In progress", "")) | AX37: 244397 | AY37: 244419 | AZ37: =IF(AY37<>"", "Complete", IF(AX37<>"", "In progress", "")) -> Complete | BF37: =IF(BE37<>"", "Complete", IF(BD37<>"", "In progress", "")) | BI37: =IF(BH37<>"", "Complete", IF(BG37<>"", "In progress", ""))
